26-Feb-22 22:54:17 - WARNING : GET http://10.86.36.130:9200/ [status:N/A request:10.005s]
Traceback (most recent call last):
  File "C:\Users\murat.yildirim2\PycharmProjects\CatchME\venv\lib\site-packages\urllib3\connection.py", line 175, in _new_conn
    (self._dns_host, self.port), self.timeout, **extra_kw
  File "C:\Users\murat.yildirim2\PycharmProjects\CatchME\venv\lib\site-packages\urllib3\util\connection.py", line 95, in create_connection
    raise err
  File "C:\Users\murat.yildirim2\PycharmProjects\CatchME\venv\lib\site-packages\urllib3\util\connection.py", line 85, in create_connection
    sock.connect(sa)
socket.timeout: timed out

During handling of the above exception, another exception occurred:

Traceback (most recent call last):
  File "C:\Users\murat.yildirim2\PycharmProjects\CatchME\venv\lib\site-packages\elasticsearch\connection\http_urllib3.py", line 256, in perform_request
    method, url, body, retries=Retry(False), headers=request_headers, **kw
  File "C:\Users\murat.yildirim2\PycharmProjects\CatchME\venv\lib\site-packages\urllib3\connectionpool.py", line 786, in urlopen
    method, url, error=e, _pool=self, _stacktrace=sys.exc_info()[2]
  File "C:\Users\murat.yildirim2\PycharmProjects\CatchME\venv\lib\site-packages\urllib3\util\retry.py", line 525, in increment
    raise six.reraise(type(error), error, _stacktrace)
  File "C:\Users\murat.yildirim2\PycharmProjects\CatchME\venv\lib\site-packages\urllib3\packages\six.py", line 770, in reraise
    raise value
  File "C:\Users\murat.yildirim2\PycharmProjects\CatchME\venv\lib\site-packages\urllib3\connectionpool.py", line 710, in urlopen
    chunked=chunked,
  File "C:\Users\murat.yildirim2\PycharmProjects\CatchME\venv\lib\site-packages\urllib3\connectionpool.py", line 398, in _make_request
    conn.request(method, url, **httplib_request_kw)
  File "C:\Users\murat.yildirim2\PycharmProjects\CatchME\venv\lib\site-packages\urllib3\connection.py", line 239, in request
    super(HTTPConnection, self).request(method, url, body=body, headers=headers)
  File "C:\Program Files\Python\lib\http\client.py", line 1252, in request
    self._send_request(method, url, body, headers, encode_chunked)
  File "C:\Program Files\Python\lib\http\client.py", line 1298, in _send_request
    self.endheaders(body, encode_chunked=encode_chunked)
  File "C:\Program Files\Python\lib\http\client.py", line 1247, in endheaders
    self._send_output(message_body, encode_chunked=encode_chunked)
  File "C:\Program Files\Python\lib\http\client.py", line 1026, in _send_output
    self.send(msg)
  File "C:\Program Files\Python\lib\http\client.py", line 966, in send
    self.connect()
  File "C:\Users\murat.yildirim2\PycharmProjects\CatchME\venv\lib\site-packages\urllib3\connection.py", line 205, in connect
    conn = self._new_conn()
  File "C:\Users\murat.yildirim2\PycharmProjects\CatchME\venv\lib\site-packages\urllib3\connection.py", line 182, in _new_conn
    % (self.host, self.timeout),
urllib3.exceptions.ConnectTimeoutError: (<urllib3.connection.HTTPConnection object at 0x000000FA9F48E748>, 'Connection to 10.86.36.130 timed out. (connect timeout=10)')
26-Feb-22 22:54:17 - WARNING : cannot connect to ElasticSearch trying again...
26-Feb-22 22:54:21 - WARNING : GET http://10.86.36.130:9200/ [status:N/A request:4.509s]
Traceback (most recent call last):
  File "C:\Users\murat.yildirim2\PycharmProjects\CatchME\venv\lib\site-packages\urllib3\connectionpool.py", line 710, in urlopen
    chunked=chunked,
  File "C:\Users\murat.yildirim2\PycharmProjects\CatchME\venv\lib\site-packages\urllib3\connectionpool.py", line 449, in _make_request
    six.raise_from(e, None)
  File "<string>", line 3, in raise_from
  File "C:\Users\murat.yildirim2\PycharmProjects\CatchME\venv\lib\site-packages\urllib3\connectionpool.py", line 444, in _make_request
    httplib_response = conn.getresponse()
  File "C:\Program Files\Python\lib\http\client.py", line 1344, in getresponse
    response.begin()
  File "C:\Program Files\Python\lib\http\client.py", line 306, in begin
    version, status, reason = self._read_status()
  File "C:\Program Files\Python\lib\http\client.py", line 267, in _read_status
    line = str(self.fp.readline(_MAXLINE + 1), "iso-8859-1")
  File "C:\Program Files\Python\lib\socket.py", line 589, in readinto
    return self._sock.recv_into(b)
ConnectionResetError: [WinError 10054] An existing connection was forcibly closed by the remote host

During handling of the above exception, another exception occurred:

Traceback (most recent call last):
  File "C:\Users\murat.yildirim2\PycharmProjects\CatchME\venv\lib\site-packages\elasticsearch\connection\http_urllib3.py", line 256, in perform_request
    method, url, body, retries=Retry(False), headers=request_headers, **kw
  File "C:\Users\murat.yildirim2\PycharmProjects\CatchME\venv\lib\site-packages\urllib3\connectionpool.py", line 786, in urlopen
    method, url, error=e, _pool=self, _stacktrace=sys.exc_info()[2]
  File "C:\Users\murat.yildirim2\PycharmProjects\CatchME\venv\lib\site-packages\urllib3\util\retry.py", line 525, in increment
    raise six.reraise(type(error), error, _stacktrace)
  File "C:\Users\murat.yildirim2\PycharmProjects\CatchME\venv\lib\site-packages\urllib3\packages\six.py", line 769, in reraise
    raise value.with_traceback(tb)
  File "C:\Users\murat.yildirim2\PycharmProjects\CatchME\venv\lib\site-packages\urllib3\connectionpool.py", line 710, in urlopen
    chunked=chunked,
  File "C:\Users\murat.yildirim2\PycharmProjects\CatchME\venv\lib\site-packages\urllib3\connectionpool.py", line 449, in _make_request
    six.raise_from(e, None)
  File "<string>", line 3, in raise_from
  File "C:\Users\murat.yildirim2\PycharmProjects\CatchME\venv\lib\site-packages\urllib3\connectionpool.py", line 444, in _make_request
    httplib_response = conn.getresponse()
  File "C:\Program Files\Python\lib\http\client.py", line 1344, in getresponse
    response.begin()
  File "C:\Program Files\Python\lib\http\client.py", line 306, in begin
    version, status, reason = self._read_status()
  File "C:\Program Files\Python\lib\http\client.py", line 267, in _read_status
    line = str(self.fp.readline(_MAXLINE + 1), "iso-8859-1")
  File "C:\Program Files\Python\lib\socket.py", line 589, in readinto
    return self._sock.recv_into(b)
urllib3.exceptions.ProtocolError: ('Connection aborted.', ConnectionResetError(10054, 'An existing connection was forcibly closed by the remote host', None, 10054, None))
26-Feb-22 22:54:21 - WARNING : cannot connect to ElasticSearch trying again...
26-Feb-22 22:54:31 - WARNING : GET http://10.86.36.130:9200/ [status:N/A request:10.002s]
Traceback (most recent call last):
  File "C:\Users\murat.yildirim2\PycharmProjects\CatchME\venv\lib\site-packages\urllib3\connection.py", line 175, in _new_conn
    (self._dns_host, self.port), self.timeout, **extra_kw
  File "C:\Users\murat.yildirim2\PycharmProjects\CatchME\venv\lib\site-packages\urllib3\util\connection.py", line 95, in create_connection
    raise err
  File "C:\Users\murat.yildirim2\PycharmProjects\CatchME\venv\lib\site-packages\urllib3\util\connection.py", line 85, in create_connection
    sock.connect(sa)
socket.timeout: timed out

During handling of the above exception, another exception occurred:

Traceback (most recent call last):
  File "C:\Users\murat.yildirim2\PycharmProjects\CatchME\venv\lib\site-packages\elasticsearch\connection\http_urllib3.py", line 256, in perform_request
    method, url, body, retries=Retry(False), headers=request_headers, **kw
  File "C:\Users\murat.yildirim2\PycharmProjects\CatchME\venv\lib\site-packages\urllib3\connectionpool.py", line 786, in urlopen
    method, url, error=e, _pool=self, _stacktrace=sys.exc_info()[2]
  File "C:\Users\murat.yildirim2\PycharmProjects\CatchME\venv\lib\site-packages\urllib3\util\retry.py", line 525, in increment
    raise six.reraise(type(error), error, _stacktrace)
  File "C:\Users\murat.yildirim2\PycharmProjects\CatchME\venv\lib\site-packages\urllib3\packages\six.py", line 770, in reraise
    raise value
  File "C:\Users\murat.yildirim2\PycharmProjects\CatchME\venv\lib\site-packages\urllib3\connectionpool.py", line 710, in urlopen
    chunked=chunked,
  File "C:\Users\murat.yildirim2\PycharmProjects\CatchME\venv\lib\site-packages\urllib3\connectionpool.py", line 398, in _make_request
    conn.request(method, url, **httplib_request_kw)
  File "C:\Users\murat.yildirim2\PycharmProjects\CatchME\venv\lib\site-packages\urllib3\connection.py", line 239, in request
    super(HTTPConnection, self).request(method, url, body=body, headers=headers)
  File "C:\Program Files\Python\lib\http\client.py", line 1252, in request
    self._send_request(method, url, body, headers, encode_chunked)
  File "C:\Program Files\Python\lib\http\client.py", line 1298, in _send_request
    self.endheaders(body, encode_chunked=encode_chunked)
  File "C:\Program Files\Python\lib\http\client.py", line 1247, in endheaders
    self._send_output(message_body, encode_chunked=encode_chunked)
  File "C:\Program Files\Python\lib\http\client.py", line 1026, in _send_output
    self.send(msg)
  File "C:\Program Files\Python\lib\http\client.py", line 966, in send
    self.connect()
  File "C:\Users\murat.yildirim2\PycharmProjects\CatchME\venv\lib\site-packages\urllib3\connection.py", line 205, in connect
    conn = self._new_conn()
  File "C:\Users\murat.yildirim2\PycharmProjects\CatchME\venv\lib\site-packages\urllib3\connection.py", line 182, in _new_conn
    % (self.host, self.timeout),
urllib3.exceptions.ConnectTimeoutError: (<urllib3.connection.HTTPConnection object at 0x000000FA9F727208>, 'Connection to 10.86.36.130 timed out. (connect timeout=10)')
26-Feb-22 22:54:31 - WARNING : cannot connect to ElasticSearch trying again...
26-Feb-22 22:54:41 - WARNING : GET http://10.86.36.130:9200/ [status:N/A request:10.001s]
Traceback (most recent call last):
  File "C:\Users\murat.yildirim2\PycharmProjects\CatchME\venv\lib\site-packages\urllib3\connection.py", line 175, in _new_conn
    (self._dns_host, self.port), self.timeout, **extra_kw
  File "C:\Users\murat.yildirim2\PycharmProjects\CatchME\venv\lib\site-packages\urllib3\util\connection.py", line 95, in create_connection
    raise err
  File "C:\Users\murat.yildirim2\PycharmProjects\CatchME\venv\lib\site-packages\urllib3\util\connection.py", line 85, in create_connection
    sock.connect(sa)
socket.timeout: timed out

During handling of the above exception, another exception occurred:

Traceback (most recent call last):
  File "C:\Users\murat.yildirim2\PycharmProjects\CatchME\venv\lib\site-packages\elasticsearch\connection\http_urllib3.py", line 256, in perform_request
    method, url, body, retries=Retry(False), headers=request_headers, **kw
  File "C:\Users\murat.yildirim2\PycharmProjects\CatchME\venv\lib\site-packages\urllib3\connectionpool.py", line 786, in urlopen
    method, url, error=e, _pool=self, _stacktrace=sys.exc_info()[2]
  File "C:\Users\murat.yildirim2\PycharmProjects\CatchME\venv\lib\site-packages\urllib3\util\retry.py", line 525, in increment
    raise six.reraise(type(error), error, _stacktrace)
  File "C:\Users\murat.yildirim2\PycharmProjects\CatchME\venv\lib\site-packages\urllib3\packages\six.py", line 770, in reraise
    raise value
  File "C:\Users\murat.yildirim2\PycharmProjects\CatchME\venv\lib\site-packages\urllib3\connectionpool.py", line 710, in urlopen
    chunked=chunked,
  File "C:\Users\murat.yildirim2\PycharmProjects\CatchME\venv\lib\site-packages\urllib3\connectionpool.py", line 398, in _make_request
    conn.request(method, url, **httplib_request_kw)
  File "C:\Users\murat.yildirim2\PycharmProjects\CatchME\venv\lib\site-packages\urllib3\connection.py", line 239, in request
    super(HTTPConnection, self).request(method, url, body=body, headers=headers)
  File "C:\Program Files\Python\lib\http\client.py", line 1252, in request
    self._send_request(method, url, body, headers, encode_chunked)
  File "C:\Program Files\Python\lib\http\client.py", line 1298, in _send_request
    self.endheaders(body, encode_chunked=encode_chunked)
  File "C:\Program Files\Python\lib\http\client.py", line 1247, in endheaders
    self._send_output(message_body, encode_chunked=encode_chunked)
  File "C:\Program Files\Python\lib\http\client.py", line 1026, in _send_output
    self.send(msg)
  File "C:\Program Files\Python\lib\http\client.py", line 966, in send
    self.connect()
  File "C:\Users\murat.yildirim2\PycharmProjects\CatchME\venv\lib\site-packages\urllib3\connection.py", line 205, in connect
    conn = self._new_conn()
  File "C:\Users\murat.yildirim2\PycharmProjects\CatchME\venv\lib\site-packages\urllib3\connection.py", line 182, in _new_conn
    % (self.host, self.timeout),
urllib3.exceptions.ConnectTimeoutError: (<urllib3.connection.HTTPConnection object at 0x000000FA9F72CA48>, 'Connection to 10.86.36.130 timed out. (connect timeout=10)')
26-Feb-22 22:54:41 - WARNING : cannot connect to ElasticSearch trying again...
26-Feb-22 22:54:51 - WARNING : GET http://10.86.36.130:9200/ [status:N/A request:10.001s]
Traceback (most recent call last):
  File "C:\Users\murat.yildirim2\PycharmProjects\CatchME\venv\lib\site-packages\urllib3\connection.py", line 175, in _new_conn
    (self._dns_host, self.port), self.timeout, **extra_kw
  File "C:\Users\murat.yildirim2\PycharmProjects\CatchME\venv\lib\site-packages\urllib3\util\connection.py", line 95, in create_connection
    raise err
  File "C:\Users\murat.yildirim2\PycharmProjects\CatchME\venv\lib\site-packages\urllib3\util\connection.py", line 85, in create_connection
    sock.connect(sa)
socket.timeout: timed out

During handling of the above exception, another exception occurred:

Traceback (most recent call last):
  File "C:\Users\murat.yildirim2\PycharmProjects\CatchME\venv\lib\site-packages\elasticsearch\connection\http_urllib3.py", line 256, in perform_request
    method, url, body, retries=Retry(False), headers=request_headers, **kw
  File "C:\Users\murat.yildirim2\PycharmProjects\CatchME\venv\lib\site-packages\urllib3\connectionpool.py", line 786, in urlopen
    method, url, error=e, _pool=self, _stacktrace=sys.exc_info()[2]
  File "C:\Users\murat.yildirim2\PycharmProjects\CatchME\venv\lib\site-packages\urllib3\util\retry.py", line 525, in increment
    raise six.reraise(type(error), error, _stacktrace)
  File "C:\Users\murat.yildirim2\PycharmProjects\CatchME\venv\lib\site-packages\urllib3\packages\six.py", line 770, in reraise
    raise value
  File "C:\Users\murat.yildirim2\PycharmProjects\CatchME\venv\lib\site-packages\urllib3\connectionpool.py", line 710, in urlopen
    chunked=chunked,
  File "C:\Users\murat.yildirim2\PycharmProjects\CatchME\venv\lib\site-packages\urllib3\connectionpool.py", line 398, in _make_request
    conn.request(method, url, **httplib_request_kw)
  File "C:\Users\murat.yildirim2\PycharmProjects\CatchME\venv\lib\site-packages\urllib3\connection.py", line 239, in request
    super(HTTPConnection, self).request(method, url, body=body, headers=headers)
  File "C:\Program Files\Python\lib\http\client.py", line 1252, in request
    self._send_request(method, url, body, headers, encode_chunked)
  File "C:\Program Files\Python\lib\http\client.py", line 1298, in _send_request
    self.endheaders(body, encode_chunked=encode_chunked)
  File "C:\Program Files\Python\lib\http\client.py", line 1247, in endheaders
    self._send_output(message_body, encode_chunked=encode_chunked)
  File "C:\Program Files\Python\lib\http\client.py", line 1026, in _send_output
    self.send(msg)
  File "C:\Program Files\Python\lib\http\client.py", line 966, in send
    self.connect()
  File "C:\Users\murat.yildirim2\PycharmProjects\CatchME\venv\lib\site-packages\urllib3\connection.py", line 205, in connect
    conn = self._new_conn()
  File "C:\Users\murat.yildirim2\PycharmProjects\CatchME\venv\lib\site-packages\urllib3\connection.py", line 182, in _new_conn
    % (self.host, self.timeout),
urllib3.exceptions.ConnectTimeoutError: (<urllib3.connection.HTTPConnection object at 0x000000FA9F7271C8>, 'Connection to 10.86.36.130 timed out. (connect timeout=10)')
26-Feb-22 22:54:51 - WARNING : cannot connect to ElasticSearch trying again...
26-Feb-22 22:54:56 - WARNING : GET http://10.86.36.130:9200/ [status:N/A request:4.512s]
Traceback (most recent call last):
  File "C:\Users\murat.yildirim2\PycharmProjects\CatchME\venv\lib\site-packages\urllib3\connectionpool.py", line 710, in urlopen
    chunked=chunked,
  File "C:\Users\murat.yildirim2\PycharmProjects\CatchME\venv\lib\site-packages\urllib3\connectionpool.py", line 449, in _make_request
    six.raise_from(e, None)
  File "<string>", line 3, in raise_from
  File "C:\Users\murat.yildirim2\PycharmProjects\CatchME\venv\lib\site-packages\urllib3\connectionpool.py", line 444, in _make_request
    httplib_response = conn.getresponse()
  File "C:\Program Files\Python\lib\http\client.py", line 1344, in getresponse
    response.begin()
  File "C:\Program Files\Python\lib\http\client.py", line 306, in begin
    version, status, reason = self._read_status()
  File "C:\Program Files\Python\lib\http\client.py", line 267, in _read_status
    line = str(self.fp.readline(_MAXLINE + 1), "iso-8859-1")
  File "C:\Program Files\Python\lib\socket.py", line 589, in readinto
    return self._sock.recv_into(b)
ConnectionResetError: [WinError 10054] An existing connection was forcibly closed by the remote host

During handling of the above exception, another exception occurred:

Traceback (most recent call last):
  File "C:\Users\murat.yildirim2\PycharmProjects\CatchME\venv\lib\site-packages\elasticsearch\connection\http_urllib3.py", line 256, in perform_request
    method, url, body, retries=Retry(False), headers=request_headers, **kw
  File "C:\Users\murat.yildirim2\PycharmProjects\CatchME\venv\lib\site-packages\urllib3\connectionpool.py", line 786, in urlopen
    method, url, error=e, _pool=self, _stacktrace=sys.exc_info()[2]
  File "C:\Users\murat.yildirim2\PycharmProjects\CatchME\venv\lib\site-packages\urllib3\util\retry.py", line 525, in increment
    raise six.reraise(type(error), error, _stacktrace)
  File "C:\Users\murat.yildirim2\PycharmProjects\CatchME\venv\lib\site-packages\urllib3\packages\six.py", line 769, in reraise
    raise value.with_traceback(tb)
  File "C:\Users\murat.yildirim2\PycharmProjects\CatchME\venv\lib\site-packages\urllib3\connectionpool.py", line 710, in urlopen
    chunked=chunked,
  File "C:\Users\murat.yildirim2\PycharmProjects\CatchME\venv\lib\site-packages\urllib3\connectionpool.py", line 449, in _make_request
    six.raise_from(e, None)
  File "<string>", line 3, in raise_from
  File "C:\Users\murat.yildirim2\PycharmProjects\CatchME\venv\lib\site-packages\urllib3\connectionpool.py", line 444, in _make_request
    httplib_response = conn.getresponse()
  File "C:\Program Files\Python\lib\http\client.py", line 1344, in getresponse
    response.begin()
  File "C:\Program Files\Python\lib\http\client.py", line 306, in begin
    version, status, reason = self._read_status()
  File "C:\Program Files\Python\lib\http\client.py", line 267, in _read_status
    line = str(self.fp.readline(_MAXLINE + 1), "iso-8859-1")
  File "C:\Program Files\Python\lib\socket.py", line 589, in readinto
    return self._sock.recv_into(b)
urllib3.exceptions.ProtocolError: ('Connection aborted.', ConnectionResetError(10054, 'An existing connection was forcibly closed by the remote host', None, 10054, None))
26-Feb-22 22:54:56 - WARNING : cannot connect to ElasticSearch trying again...
26-Feb-22 22:55:13 - WARNING : connected to ElasticSearch
26-Feb-22 22:55:13 - WARNING : 1 of 1: unxmysqldb01
26-Feb-22 22:55:13 - WARNING : cpu dataFrame created for unxmysqldb01
26-Feb-22 22:55:13 - WARNING : found unxmysqldb01_cpu_model.pkl
26-Feb-22 22:55:13 - WARNING : found unxmysqldb01_cpu_scaler.pkl
26-Feb-22 22:55:14 - WARNING : predict cpu data for unxmysqldb01
26-Feb-22 22:55:14 - WARNING : no cpu anomaly detect for unxmysqldb01
26-Feb-22 22:55:14 - WARNING : memory dataFrame created for unxmysqldb01
26-Feb-22 22:55:14 - WARNING : found unxmysqldb01_memory_model.pkl
26-Feb-22 22:55:14 - WARNING : found unxmysqldb01_memory_scaler.pkl
26-Feb-22 22:55:14 - WARNING : predict memory data for unxmysqldb01
26-Feb-22 22:55:14 - WARNING : no memory anomaly detect for unxmysqldb01
26-Feb-22 22:55:14 - WARNING : load dataFrame created for unxmysqldb01
26-Feb-22 22:55:14 - WARNING : found unxmysqldb01_load_model.pkl
26-Feb-22 22:55:14 - WARNING : found unxmysqldb01_load_scaler.pkl
26-Feb-22 22:55:14 - WARNING : predict load data for unxmysqldb01
26-Feb-22 22:55:14 - WARNING : no load anomaly detect for unxmysqldb01
26-Feb-22 22:55:14 - WARNING : socket_summary dataFrame created for unxmysqldb01
26-Feb-22 22:55:14 - WARNING : found unxmysqldb01_socket_summary_model.pkl
26-Feb-22 22:55:14 - WARNING : found unxmysqldb01_socket_summary_scaler.pkl
26-Feb-22 22:55:14 - WARNING : predict socket_summary data for unxmysqldb01
26-Feb-22 22:55:14 - WARNING : no socket_summary anomaly detect for unxmysqldb01
26-Feb-22 22:55:14 - WARNING : process_summary dataFrame created for unxmysqldb01
26-Feb-22 22:55:14 - WARNING : found unxmysqldb01_process_summary_model.pkl
26-Feb-22 22:55:14 - WARNING : found unxmysqldb01_process_summary_scaler.pkl
26-Feb-22 22:55:14 - WARNING : predict process_summary data for unxmysqldb01
26-Feb-22 22:55:14 - WARNING : no process_summary anomaly detect for unxmysqldb01
26-Feb-22 22:55:14 - WARNING : found unxmysqldb01_ALL_model.pkl
26-Feb-22 22:55:14 - WARNING : found unxmysqldb01_ALL_scaler.pkl
26-Feb-22 22:55:15 - WARNING : predict ALL data for unxmysqldb01
26-Feb-22 22:55:15 - WARNING : no ALL anomaly detect for unxmysqldb01
26-Feb-22 22:55:15 - WARNING : created unxmysqldb01_result dataFrame
26-Feb-22 22:55:16 - WARNING : inserting to es index: dev_catchme_2022.02.26 for unxmysqldb01
26-Feb-22 22:55:16 - WARNING : the predictAll script end for unxmysqldb01

